Workbook

Sheet Old
A1: Nom du Jury:
A2: Thème | B2: Critère | C2: Description | D2: Score | E2: UC #6 Smart affectation de tickets Jira | F2: UC #1 Système de pré-positionnement GO en village | G2: UC #2 Préconisation d’achat selon la saisonnalité et aide à la négociation | H2: UC #3 RAG Externe (Infos produit) | I2: UC #4 Recherche documentaire interne (RAG) | J2: UC #5 Marketing Content Versioning
A3: Adéquation au problème | B3: Compréhension du problème | C3: L’équipe a-t-elle bien compris et défini le problème? | D3: 10
B4: Pertinence de la solution | C4: La solution proposée répond-elle efficacement au problème identifié ? | D4: 10
A5: Originalité de la solution | B5: Innovation | C5: La solution est-elle innovante et créative ? | D5: 10
B6: Différenciation | C6: En quoi la solution se distingue-t-elle des approches existantes ? | D6: 5
A7: Degré de finalisation | B7: Fonctionnalité | C7: La solution est-elle fonctionnelle et utilisable ? | D7: 10
B8: Stabilité | C8: La solution fonctionne-t-elle sans bugs majeurs ? | D8: 10
A9: Qualité du code | B9: Lisibilité | C9: Le code est-il bien structuré et facile à lire ? | D9: 10
B10: Bonne pratique | C10: Le code suit-il les bonnes pratiques de développement (modularité, etc.) ? | D10: 5
B11: Documentation du code | C11: Le code est-il bien documenté avec des commentaires pertinents ? | D11: 5
A12: Clarté de la présentation | B12: Structure de la présentation | C12: La présentation est-elle bien structurée et facile à suivre ? | D12: 5
B13: Communication | C13: Les présentateurs ont-ils bien communiqué les points clés et répondu aux questions de manière efficace ? | D13: 5
B14: Démo de la solution | C14: La démonstration de la solution a-t-elle été claire et convaincante ? | D14: 5
A15: Rentabilité de la solution | B15: Viabilité économique | C15: La solution a-t-elle un potentiel de rentabilité ou d'économie significative ? | D15: 5
B16: Impact sur les coûts | C16: La solution permet-elle de réduire les coûts ou d'augmenter les revenus de manière significative ? | D16: 5
A17: TOTAL | D17: 100

Sheet Jury Proposition
A1: Nom du Jury:
A2: Thème | B2: Critère | C2: Description | D2: Score | E2: Commentaires | F2: UC# | G2: UC# | H2: UC# | I2: UC# | J2: UC# | K2: UC#
A3: Valeur Business & Impact métier | B3: Impact métier | C3: Le cas d’usage adresse-t-il un pain point concret (coûts, délais, qualité, satisfaction client, risques…) ? | E3: Point éliminant
B4: Automatisation | C4: Est-ce que la sloution identiféé contribue à automatiser tout un process ?
B5: Viabilité économique | C5: La solution a-t-elle un potentiel de rentabilité ou d'économie significative ?
B6: Impact sur les coûts | C6: La solution permet-elle de réduire les coûts ou d'augmenter les revenus de manière significative ?
A7: Alignement stratégique Club Med | C7: Est-ce que la solution sert elle la stratégie globale Club med, pas juste un cas métier isolé ? | E7: référence à la grille dans la fiche de qualif
A8: Qualité de la qualification fonctionnelle | B8: Pertinence de la solution | C8: La solution proposée répond-elle efficacement au problème identifié ? | E8: red flag - on met pas de l'IA parce que c'est le thème
A9: Faisabilité data & technique | B9: Fonctionnalité | C9: La solution est-elle fonctionnelle et utilisable ? | E9: Peut-on en faire quelque chose de concret en quelques jours de hackathon ?
B10: Stabilité | C10: La solution fonctionne-t-elle sans bugs majeurs ?
B11: Scalabilité | C11: Est-il possible de mutualiser les technos utilisées ?
B12: Maturité | C12: Maturité suffisante pour un POC / hackathon
A13: Adoption & opérationnalisation | C13: Bénéfices clairs pour les utilisateurs finaux
C14: Besoin de conduite du changement identifié
A15: Clarté de la présentation | B15: Structure de la présentation | C15: La présentation est-elle bien structurée et facile à suivre ?
B16: Communication | C16: Les présentateurs ont-ils bien communiqué les points clés et répondu aux questions de manière efficace ?
B17: Démo de la solution | C17: La démonstration de la solution a-t-elle été claire et convaincante ?
A18: Originalité de la solution | B18: Innovation | C18: La solution est-elle innovante et créative ?
B19: Différenciation | C19: En quoi la solution se distingue-t-elle des approches existantes ?
A20: Potentiel Hackathon Microsoft | B20: Compatibilité avec écosystème Microsoft | C20: Copilot / Azure AI Power Platform Data / intégrations

Sheet LDAP_Security_ID_Creation
B2: Use case # 1 | C2: LDAP_Security_ID_Creation
B3: Thème | C3: Critère | D3: Description | E3: Echelle | F3: Cédric Baillet | G3: Nicolas Bresch | H3: Quentin Briard | I3: Nicolas Caussin | J3: Amina Chaabane | K3: Siddhartha Chatterjee | L3: Julien Denis | M3: Caroline Launois-Beaurain | N3: Armelle Vimont Laurent | O3: Sophie Parisot Bouelam | P3: Franck Picabea | Q3: Yoann Spadavecchia | R3: Richard Douville | S3: Score (0–5) | T3: Score Final
B4: Valeur Business | T4: =AVERAGE(S5:S9) -> 2.7666667
C5: Impact métier | D5: A quel point le cas d’usage adresse-t-il un pain point clair, prioritaire et concret (coûts, délais, qualité, satisfaction client, risques) ? | E5: 0 = aucun paint point identifié / 5 = pain point avec fort impact et reconnu | F5: 4 | G5: 4 | H5: 4 | I5: 4 | J5: 4 | L5: 3 | M5: 3 | N5: 3 | O5: 3 | P5: 3 | Q5: 3 | R5: 3 | S5: =AVERAGE(F5:R5) -> 3.4166667
C6: Viabilité économique | D6: A quel point le cas d'usage présente-t-il un potentiel de ROI crédible et réaliste (économies, gains de productivité, amélioration de la qualité) ? | E6: 0 = aucun ROI objectivé / 5 = ROI clair et élévé | F6: 1 | G6: 2 | H6: 1 | I6: 4 | J6: 3 | L6: 4 | M6: 3 | N6: 4 | O6: 4 | P6: 1 | Q6: 4 | R6: 2 | S6: =AVERAGE(F6:R6) -> 2.75
C7: Automatisation | D7: A quel niveau la solution permet-elle d’automatiser un processus métier (vs simple aide ponctuelle) ? | E7: 0 = aide marginale / 5 = automatisation de bout en bout | F7: 3 | G7: 2 | H7: 3 | I7: 5 | J7: 4 | L7: 5 | M7: 3 | N7: 4 | O7: 4 | P7: 3 | Q7: 3 | R7: 3 | S7: =AVERAGE(F7:R7) -> 3.5
C8: Effet différenciant | D8: Ce cas d’usage a-t-il un potentiel de transformation visible ("whaou") pour nos métiers ou clients ? | E8: 0 – Aucun effet différenciant / 5 – Effet “Whaou” stratégique | F8: 1 | G8: 3 | H8: 3 | I8: 2 | J8: 2 | L8: 1 | M8: 2 | N8: 1 | O8: 2 | P8: 3 | Q8: 1 | R8: 1 | S8: =AVERAGE(F8:R8) -> 1.8333333
C9: Cohérence stratégique | D9: A quel point le cas d’usage est aligné avec les priorités stratégiques Club Med (excellence opérationnelle, expérience client, scalabilité) au-delà d'un besoin local ? | E9: 0 = aucun lien avec la stratégie / 5 = alignement majeur | F9: 3 | G9: 2 | H9: 2 | I9: 3 | J9: 3 | L9: 3 | M9: 2 | N9: 2 | O9: 2 | P9: 2 | Q9: 2 | R9: 2 | S9: =AVERAGE(F9:R9) -> 2.3333333
B10: Maturité du Use Case | T10: =AVERAGE(S11:S15) -> 3.2163636
C11: Qualité du cadrage fonctionnel | D11: A quel niveau le périmètre, les objectifs et les hypothèses sont-ils clairement définis ? | E11: 0 = très flou / 5 = cadrage exemplaire | F11: 4 | G11: 3 | H11: 3 | I11: 4 | J11: 4 | L11: 3 | M11: 2 | N11: 2 | O11: 2 | P11: 3 | Q11: 2 | R11: 3 | S11: =+AVERAGE(F11:R11) -> 2.9166667
C12: Accessibilité / Disponiblité des données | D12: A quel point les données nécessaires sont-elles identifiées, existantes et accessibles (CRM, formulaires, historiques, etc.) ? | E12: 0 = données inexistantes / 5 = données prêtes à l'emploi | F12: 5 | G12: 4 | H12: 3 | I12: 4 | J12: 4 | L12: 4 | M12: 4 | N12: 4 | O12: 4 | P12: 3 | Q12: 5 | R12: 5 | S12: =+AVERAGE(F12:R12) -> 4.0833333
C13: Maturité POC / Hackathon | D13: Compte tenu des données, du cadrage et des dépendances, peut-on produire un résultat concret en hackathon ? | E13: 0 = irréaliste / 3 = squads / 5 = hackaton ready | F13: 4 | G13: 2 | H13: 3 | I13: 3 | L13: 3 | M13: 3 | N13: 4 | O13: 4 | P13: 3 | Q13: 5 | R13: 4 | S13: =+AVERAGE(F13:R13) -> 3.4545455
C14: Scalabilité technique | D14: Dans quelle mesure les technologies envisagées sont-elles mutualisables et industrialisables ? | E14: 0 = non scalable / 5 = scalabilité native | F14: 1 | G14: 2 | H14: 1 | I14: 3 | L14: 5 | M14: 1 | N14: 1 | O14: 1 | P14: 1 | Q14: 1 | R14: 2 | S14: =+AVERAGE(F14:R14) -> 1.7272727
C15: Confidentialité des données | D15: A quel point les enjeux de confidentialité, de sécurité et de conformité RGPD sont ils maîtrisés et compatibles avec une mise en œuvre de ce cas d'usage ? | E15: 0 = risque majeur / 5 = conformité by design | F15: 4 | G15: 4 | H15: 4 | I15: 5 | L15: 1 | N15: 5 | O15: 4 | P15: 3 | Q15: 5 | R15: 4 | S15: =+AVERAGE(F15:R15) -> 3.9
B17: RESULTATS CONSOLIDES
B18: Ce scoring vous permettra de projeter ces différents cas d'usage sur la matrice pour une vue consolidée finale.
B20: =B4 -> Valeur Business | C20: =T4 -> 2.7666667 | D20: =IF(C20<2.5,"Faible",IF(AND(C20>=2.5,C20<4),"Moyen","Fort")) -> Moyen
B21: =B10 -> Maturité du Use Case | C21: =T10 -> 3.2163636 | D21: =IF(C21<2.5,"Faible",IF(AND(C21>=2.5,C21<4),"Moyen","Fort")) -> Moyen
B24: POSITIONNEMENT FINAL : - Sélectionné pour le hackathon - Backlog pour les squads IA - A développer en self-service
B26: =IF(C20<3,"Hors priorité", IF(AND(C20>=4,C21>=4),"Hackathon", IF(AND(C20>=4,C21<4),"Backlog projet", IF(AND(C20>=3,C20<4,C21>=4),"Self AI (Copilot Studio)", "Backlog projet" ) ) ) ) -> Hors priorité
B28: Légende :
B29: Valeur < 3 - Hors priorité Valeur ≥ 4 & Faisabilité ≥ 4 - Hackathon Valeur ≥ 4 & Faisabilité < 4 - Backlog projet Valeur entre 3 et <4 & Faisabilité ≥ 4 - Self AI Autre - Backlog projet (par défaut)

Sheet strategic reporting
B2: Use case # 2 | C2: Automation for strategic reporting - AI Data driven approach to operations financial management
B3: Thème | C3: Critère | D3: Description | E3: Echelle | F3: Cédric Baillet | G3: Nicolas Bresch | H3: Quentin Briard | I3: Nicolas Caussin | J3: Amina Chaabane | K3: Siddhartha Chatterjee | L3: Julien Denis | M3: Caroline Launois-Beaurain | N3: Armelle Vimont Laurent | O3: Sophie Parisot Bouelam | P3: Franck Picabea | Q3: Yoann Spadavecchia | R3: Richard Douville | S3: Score (0–5) | T3: Score Final
B4: Valeur Business | T4: =AVERAGE(S5:S9) -> 2.5384615
C5: Impact métier | D5: A quel point le cas d’usage adresse-t-il un pain point clair, prioritaire et concret (coûts, délais, qualité, satisfaction client, risques) ? | E5: 0 = aucun paint point identifié / 5 = pain point avec fort impact et reconnu | F5: 3 | G5: 3 | H5: 3 | I5: 3 | J5: 3 | K5: 3 | L5: 3 | M5: 3 | N5: 3 | O5: 4 | P5: 3 | Q5: 3 | R5: 4 | S5: =AVERAGE(F5:R5) -> 3.1538462
C6: Viabilité économique | D6: A quel point le cas d'usage présente-t-il un potentiel de ROI crédible et réaliste (économies, gains de productivité, amélioration de la qualité) ? | E6: 0 = aucun ROI objectivé / 5 = ROI clair et élévé | F6: 2 | G6: 3 | H6: 2 | I6: 2 | J6: 3 | K6: 2 | L6: 1 | M6: 2 | N6: 2 | O6: 3 | P6: 2 | Q6: 2 | R6: 3 | S6: =AVERAGE(F6:R6) -> 2.2307692
C7: Automatisation | D7: A quel niveau la solution permet-elle d’automatiser un processus métier (vs simple aide ponctuelle) ? | E7: 0 = aide marginale / 5 = automatisation de bout en bout | F7: 3 | G7: 2 | H7: 2 | I7: 3 | J7: 2 | K7: 2 | L7: 2 | M7: 2 | N7: 3 | O7: 4 | P7: 3 | Q7: 3 | R7: 3 | S7: =AVERAGE(F7:R7) -> 2.6153846
C8: Effet différenciant | D8: Ce cas d’usage a-t-il un potentiel de transformation visible ("whaou") pour nos métiers ou clients ? | E8: 0 – Aucun effet différenciant / 5 – Effet “Whaou” stratégique | F8: 3 | G8: 2 | H8: 2 | I8: 3 | J8: 2 | K8: 2 | L8: 4 | M8: 3 | N8: 2 | O8: 3 | P8: 2 | Q8: 2 | R8: 2 | S8: =AVERAGE(F8:R8) -> 2.4615385
C9: Cohérence stratégique | D9: A quel point le cas d’usage est aligné avec les priorités stratégiques Club Med (excellence opérationnelle, expérience client, scalabilité) au-delà d'un besoin local ? | E9: 0 = aucun lien avec la stratégie / 5 = alignement majeur | F9: 3 | G9: 3 | H9: 2 | I9: 2 | J9: 2 | K9: 2 | L9: 2 | M9: 2 | N9: 2 | O9: 3 | P9: 2 | Q9: 2 | R9: 2 | S9: =AVERAGE(F9:R9) -> 2.2307692
B10: Maturité du Use Case | T10: =AVERAGE(S11:S15) -> 2.4733333
C11: Qualité du cadrage fonctionnel | D11: A quel niveau le périmètre, les objectifs et les hypothèses sont-ils clairement définis ? | E11: 0 = très flou / 5 = cadrage exemplaire | F11: 3 | G11: 2 | H11: 2 | I11: 3 | J11: 3 | L11: 2 | M11: 2 | N11: 2 | O11: 3 | P11: 3 | Q11: 2 | R11: 2 | S11: =+AVERAGE(F11:R11) -> 2.4166667
C12: Accessibilité / Disponiblité des données | D12: A quel point les données nécessaires sont-elles identifiées, existantes et accessibles (CRM, formulaires, historiques, etc.) ? | E12: 0 = données inexistantes / 5 = données prêtes à l'emploi | F12: 1 | G12: 1 | H12: 1 | I12: 3 | J12: 1 | L12: 2 | M12: 1 | N12: 2 | O12: 2 | P12: 2 | Q12: 3 | R12: 2 | S12: =+AVERAGE(F12:R12) -> 1.75
C13: Maturité POC / Hackathon | D13: Compte tenu des données, du cadrage et des dépendances, peut-on produire un résultat concret en hackathon ? | E13: 0 = irréaliste / 5 = hackaton ready | F13: 2 | G13: 1 | H13: 1 | I13: 2 | L13: 2 | M13: 1 | N13: 2 | O13: 3 | P13: 2 | Q13: 2 | R13: 2 | S13: =+AVERAGE(F13:R13) -> 1.8181818
C14: Scalabilité technique | D14: Dans quelle mesure les technologies envisagées sont-elles mutualisables et industrialisables ? | E14: 0 = non scalable / 5 = scalabilité native | F14: 3 | G14: 4 | H14: 3 | I14: 3 | L14: 4 | M14: 3 | N14: 2 | O14: 4 | P14: 2 | Q14: 4 | R14: 3 | S14: =+AVERAGE(F14:R14) -> 3.1818182
C15: Confidentialité des données | D15: A quel point les enjeux de confidentialité, de sécurité et de conformité RGPD sont ils maîtrisés et compatibles avec une mise en œuvre de ce cas d'usage ? | E15: 0 = risque majeur / 5 = conformité by design | F15: 2 | G15: 2 | H15: 3 | I15: 3 | L15: 2 | N15: 4 | O15: 4 | P15: 3 | Q15: 5 | R15: 4 | S15: =+AVERAGE(F15:R15) -> 3.2
B17: RESULTATS CONSOLIDES
B18: Ce scoring vous permettra de projeter ces différents cas d'usage sur la matrice pour une vue consolidée finale.
B20: =B4 -> Valeur Business | C20: =T4 -> 2.5384615 | D20: =IF(C20<2.5,"Faible",IF(AND(C20>=2.5,C20<4),"Moyen","Fort")) -> Moyen
B21: =B10 -> Maturité du Use Case | C21: =T10 -> 2.4733333 | D21: =IF(C21<2.5,"Faible",IF(AND(C21>=2.5,C21<4),"Moyen","Fort")) -> Faible
B24: POSITIONNEMENT FINAL : - Sélectionné pour le hackathon - Backlog pour les squads IA - A développer en self-service
B26: =IF(C20<3,"Hors priorité", IF(AND(C20>=4,C21>=4),"Hackathon", IF(AND(C20>=4,C21<4),"Backlog projet", IF(AND(C20>=3,C20<4,C21>=4),"Self AI (Copilot Studio)", "Backlog projet" ) ) ) ) -> Hors priorité
B28: Légende :
B29: Valeur < 3 - Hors priorité Valeur ≥ 4 & Faisabilité ≥ 4 - Hackathon Valeur ≥ 4 & Faisabilité < 4 - Backlog projet Valeur entre 3 et <4 & Faisabilité ≥ 4 - Self AI Autre - Backlog projet (par défaut)

Sheet GO Holiday
B2: Use case # 3 | C2: GO Holidays perimeter automation
B3: Thème | C3: Critère | D3: Description | E3: Echelle | F3: Cédric Baillet | G3: Nicolas Bresch | H3: Quentin Briard | I3: Nicolas Caussin | J3: Amina Chaabane | K3: Siddhartha Chatterjee | L3: Julien Denis | M3: Caroline Launois-Beaurain | N3: Armelle Vimont Laurent | O3: Sophie Parisot Bouelam | P3: Franck Picabea | Q3: Yoann Spadavecchia | R3: Richard Douville | S3: Score (0–5) | T3: Score Final
B4: Valeur Business | T4: =AVERAGE(S5:S9) -> 2.2153846
C5: Impact métier | D5: A quel point le cas d’usage adresse-t-il un pain point clair, prioritaire et concret (coûts, délais, qualité, satisfaction client, risques) ? | E5: 0 = aucun paint point identifié / 5 = pain point avec fort impact et reconnu | F5: 2 | G5: 2 | H5: 2 | I5: 3 | J5: 2 | K5: 5 | L5: 2 | M5: 2 | N5: 2 | O5: 2 | P5: 2 | Q5: 3 | R5: 2 | S5: =AVERAGE(F5:R5) -> 2.3846154
C6: Viabilité économique | D6: A quel point le cas d'usage présente-t-il un potentiel de ROI crédible et réaliste (économies, gains de productivité, amélioration de la qualité) ? | E6: 0 = aucun ROI objectivé / 5 = ROI clair et élévé | F6: 1 | G6: 1 | H6: 0 | I6: 1 | J6: 1 | K6: 1 | L6: 1 | M6: 1 | N6: 1 | O6: 4 | P6: 2 | Q6: 1 | R6: 2 | S6: =AVERAGE(F6:R6) -> 1.3076923
C7: Automatisation | D7: A quel niveau la solution permet-elle d’automatiser un processus métier (vs simple aide ponctuelle) ? | E7: 0 = aide marginale / 5 = automatisation de bout en bout | F7: 4 | G7: 5 | H7: 4 | I7: 4 | J7: 2 | K7: 4 | L7: 2 | M7: 4 | N7: 4 | O7: 4 | P7: 4 | Q7: 4 | R7: 4 | S7: =AVERAGE(F7:R7) -> 3.7692308
C8: Effet différenciant | D8: Ce cas d’usage a-t-il un potentiel de transformation visible ("whaou") pour nos métiers ou clients ? | E8: 0 – Aucun effet différenciant / 5 – Effet “Whaou” stratégique | F8: 2 | G8: 1 | H8: 3 | I8: 4 | J8: 2 | K8: 3 | L8: 3 | M8: 2 | N8: 3 | O8: 2 | P8: 3 | Q8: 1 | R8: 2 | S8: =AVERAGE(F8:R8) -> 2.3846154
C9: Cohérence stratégique | D9: A quel point le cas d’usage est aligné avec les priorités stratégiques Club Med (excellence opérationnelle, expérience client, scalabilité) au-delà d'un besoin local ? | E9: 0 = aucun lien avec la stratégie / 5 = alignement majeur | F9: 1 | G9: 2 | H9: 0 | I9: 1 | J9: 1 | K9: 4 | L9: 1 | M9: 1 | N9: 1 | O9: 1 | P9: 1 | Q9: 1 | R9: 1 | S9: =AVERAGE(F9:R9) -> 1.2307692
B10: Maturité du Use Case | T10: =AVERAGE(S11:S15) -> 3.5078089
C11: Qualité du cadrage fonctionnel | D11: A quel niveau le périmètre, les objectifs et les hypothèses sont-ils clairement définis ? | E11: 0 = très flou / 5 = cadrage exemplaire | F11: 4 | G11: 4 | H11: 2 | I11: 3 | J11: 2 | K11: 2 | L11: 3 | M11: 3 | N11: 4 | O11: 4 | P11: 2 | Q11: 3 | R11: 2 | S11: =+AVERAGE(F11:R11) -> 2.9230769
C12: Accessibilité / Disponiblité des données | D12: A quel point les données nécessaires sont-elles identifiées, existantes et accessibles (CRM, formulaires, historiques, etc.) ? | E12: 0 = données inexistantes / 5 = données prêtes à l'emploi | F12: 5 | G12: 4 | H12: 4 | I12: 5 | J12: 3 | K12: 3 | L12: 5 | M12: 4 | N12: 5 | O12: 5 | P12: 3 | Q12: 5 | R12: 3 | S12: =+AVERAGE(F12:R12) -> 4.1538462
C13: Maturité POC / Hackathon | D13: Compte tenu des données, du cadrage et des dépendances, peut-on produire un résultat concret en hackathon ? | E13: 0 = irréaliste / 5 = hackaton ready | F13: 4 | G13: 0 | H13: 4 | I13: 4 | K13: 3 | L13: 4 | M13: 4 | N13: 5 | O13: 4 | P13: 3 | Q13: 5 | R13: 3 | S13: =+AVERAGE(F13:R13) -> 3.5833333
C14: Scalabilité technique | D14: Dans quelle mesure les technologies envisagées sont-elles mutualisables et industrialisables ? | E14: 0 = non scalable / 5 = scalabilité native | F14: 1 | G14: 1 | H14: 2 | I14: 2 | K14: 3 | L14: 1 | M14: 2 | N14: 2 | O14: 4 | P14: 4 | Q14: 3 | R14: 3 | S14: =+AVERAGE(F14:R14) -> 2.3333333
C15: Confidentialité des données | D15: A quel point les enjeux de confidentialité, de sécurité et de conformité RGPD sont ils maîtrisés et compatibles avec une mise en œuvre de ce cas d'usage ? | E15: 0 = risque majeur / 5 = conformité by design | F15: 5 | G15: 5 | H15: 5 | I15: 5 | K15: 5 | L15: 4 | N15: 5 | O15: 5 | P15: 3 | Q15: 5 | R15: 3 | S15: =+AVERAGE(F15:R15) -> 4.5454545
B17: RESULTATS CONSOLIDES
B18: Ce scoring vous permettra de projeter ces différents cas d'usage sur la matrice pour une vue consolidée finale.
B20: =B4 -> Valeur Business | C20: =T4 -> 2.2153846 | D20: =IF(C20<2.5,"Faible",IF(AND(C20>=2.5,C20<4),"Moyen","Fort")) -> Faible
B21: =B10 -> Maturité du Use Case | C21: =T10 -> 3.5078089 | D21: =IF(C21<2.5,"Faible",IF(AND(C21>=2.5,C21<4),"Moyen","Fort")) -> Moyen
B24: POSITIONNEMENT FINAL : - Sélectionné pour le hackathon - Backlog pour les squads IA - A développer en self-service
B26: =IF(C20<3,"Hors priorité", IF(AND(C20>=4,C21>=4),"Hackathon", IF(AND(C20>=4,C21<4),"Backlog projet", IF(AND(C20>=3,C20<4,C21>=4),"Self AI (Copilot Studio)", "Backlog projet" ) ) ) ) -> Hors priorité
B28: Légende :
B29: Valeur < 3 - Hors priorité Valeur ≥ 4 & Faisabilité ≥ 4 - Hackathon Valeur ≥ 4 & Faisabilité < 4 - Backlog projet Valeur entre 3 et <4 & Faisabilité ≥ 4 - Self AI Autre - Backlog projet (par défaut)

Sheet Regulatory Watch
B2: Use case # 4 | C2: Regulatory watch
B3: Thème | C3: Critère | D3: Description | E3: Echelle | F3: Cédric Baillet | G3: Nicolas Bresch | H3: Quentin Briard | I3: Nicolas Caussin | J3: Amina Chaabane | K3: Siddhartha Chatterjee | L3: Julien Denis | M3: Caroline Launois-Beaurain | N3: Armelle Vimont Laurent | O3: Sophie Parisot Bouelam | P3: Franck Picabea | Q3: Yoann Spadavecchia | R3: Richard Douville | S3: Score (0–5) | T3: Score Final
B4: Valeur Business | T4: =AVERAGE(S5:S9) -> 2.95
C5: Impact métier | D5: A quel point le cas d’usage adresse-t-il un pain point clair, prioritaire et concret (coûts, délais, qualité, satisfaction client, risques) ? | E5: 0 = aucun paint point identifié / 5 = pain point avec fort impact et reconnu | F5: 4 | G5: 4 | H5: 4 | I5: 4 | J5: 4 | K5: 5 | L5: 4 | M5: 4 | N5: 5 | O5: 5 | P5: 4 | Q5: 4 | R5: 4 | S5: =AVERAGE(F5:R5) -> 4.2307692
C6: Viabilité économique | D6: A quel point le cas d'usage présente-t-il un potentiel de ROI crédible et réaliste (économies, gains de productivité, amélioration de la qualité) ? | E6: 0 = aucun ROI objectivé / 5 = ROI clair et élévé | F6: 1 | G6: 1 | H6: 1 | I6: 1 | J6: 3 | L6: 2 | M6: 2 | N6: 2 | O6: 2 | P6: 1 | Q6: 3 | R6: 2 | S6: =AVERAGE(F6:R6) -> 1.75
C7: Automatisation | D7: A quel niveau la solution permet-elle d’automatiser un processus métier (vs simple aide ponctuelle) ? | E7: 0 = aide marginale / 5 = automatisation de bout en bout | F7: 4 | G7: 3 | H7: 4 | I7: 3 | J7: 2 | K7: 4 | L7: 3 | M7: 3 | N7: 3 | O7: 3 | P7: 3 | Q7: 3 | R7: 4 | S7: =AVERAGE(F7:R7) -> 3.2307692
C8: Effet différenciant | D8: Ce cas d’usage a-t-il un potentiel de transformation visible ("whaou") pour nos métiers ou clients ? | E8: 0 – Aucun effet différenciant / 5 – Effet “Whaou” stratégique | F8: 2 | G8: 2 | H8: 2 | I8: 2 | J8: 2 | K8: 4 | L8: 3 | M8: 3 | N8: 3 | O8: 2 | P8: 3 | Q8: 3 | R8: 3 | S8: =AVERAGE(F8:R8) -> 2.6153846
C9: Cohérence stratégique | D9: A quel point le cas d’usage est aligné avec les priorités stratégiques Club Med (excellence opérationnelle, expérience client, scalabilité) au-delà d'un besoin local ? | E9: 0 = aucun lien avec la stratégie / 5 = alignement majeur | F9: 3 | G9: 2 | H9: 4 | I9: 4 | J9: 2 | K9: 4 | L9: 3 | M9: 4 | N9: 3 | O9: 4 | P9: 1 | Q9: 2 | R9: 2 | S9: =AVERAGE(F9:R9) -> 2.9230769
B10: Maturité du Use Case | T10: =AVERAGE(S11:S15) -> 3.7724942
C11: Qualité du cadrage fonctionnel | D11: A quel niveau le périmètre, les objectifs et les hypothèses sont-ils clairement définis ? | E11: 0 = très flou / 5 = cadrage exemplaire | F11: 4 | G11: 4 | H11: 4 | I11: 4 | J11: 4 | K11: 4 | L11: 3 | M11: 4 | N11: 3 | O11: 3 | P11: 3 | Q11: 4 | R11: 3 | S11: =+AVERAGE(F11:R11) -> 3.6153846
C12: Accessibilité / Disponiblité des données | D12: A quel point les données nécessaires sont-elles identifiées, existantes et accessibles (CRM, formulaires, historiques, etc.) ? | E12: 0 = données inexistantes / 5 = données prêtes à l'emploi | F12: 3 | G12: 4 | H12: 5 | I12: 3 | J12: 4 | K12: 2 | L12: 1 | M12: 4 | N12: 3 | O12: 4 | P12: 4 | Q12: 3 | R12: 3 | S12: =+AVERAGE(F12:R12) -> 3.3076923
C13: Maturité POC / Hackathon | D13: Compte tenu des données, du cadrage et des dépendances, peut-on produire un résultat concret en hackathon ? | E13: 0 = irréaliste / 5 = hackaton ready | F13: 3 | G13: 3 | H13: 5 | I13: 4 | K13: 4 | L13: 5 | M13: 4 | N13: 3 | O13: 4 | P13: 3 | Q13: 4 | R13: 3 | S13: =+AVERAGE(F13:R13) -> 3.75
C14: Scalabilité technique | D14: Dans quelle mesure les technologies envisagées sont-elles mutualisables et industrialisables ? | E14: 0 = non scalable / 5 = scalabilité native | F14: 3 | G14: 4 | H14: 5 | I14: 3 | K14: 3 | L14: 4 | M14: 4 | N14: 3 | O14: 5 | P14: 4 | Q14: 5 | R14: 4 | S14: =+AVERAGE(F14:R14) -> 3.9166667
C15: Confidentialité des données | D15: A quel point les enjeux de confidentialité, de sécurité et de conformité RGPD sont ils maîtrisés et compatibles avec une mise en œuvre de ce cas d'usage ? | E15: 0 = risque majeur / 5 = conformité by design | F15: 5 | G15: 4 | H15: 5 | I15: 5 | K15: 5 | L15: 3 | N15: 4 | O15: 5 | P15: 4 | Q15: 3 | R15: 4 | S15: =+AVERAGE(F15:R15) -> 4.2727273
B17: RESULTATS CONSOLIDES
B18: Ce scoring vous permettra de projeter ces différents cas d'usage sur la matrice pour une vue consolidée finale.
B20: =B4 -> Valeur Business | C20: =T4 -> 2.95 | D20: =IF(C20<2.5,"Faible",IF(AND(C20>=2.5,C20<4),"Moyen","Fort")) -> Moyen
B21: =B10 -> Maturité du Use Case | C21: =T10 -> 3.7724942 | D21: =IF(C21<2.5,"Faible",IF(AND(C21>=2.5,C21<4),"Moyen","Fort")) -> Moyen
B24: POSITIONNEMENT FINAL : - Sélectionné pour le hackathon - Backlog pour les squads IA - A développer en self-service
B26: =IF(C20<3,"Hors priorité", IF(AND(C20>=4,C21>=4),"Hackathon", IF(AND(C20>=4,C21<4),"Backlog projet", IF(AND(C20>=3,C20<4,C21>=4),"Self AI (Copilot Studio)", "Backlog projet" ) ) ) ) -> Hors priorité
B28: Légende :
B29: Valeur < 3 - Hors priorité Valeur ≥ 4 & Faisabilité ≥ 4 - Hackathon Valeur ≥ 4 & Faisabilité < 4 - Backlog projet Valeur entre 3 et <4 & Faisabilité ≥ 4 - Self AI Autre - Backlog projet (par défaut)

Sheet Background Check
B2: Use case # 6 | C2: Background Check
B3: Thème | C3: Critère | D3: Description | E3: Echelle | F3: Cédric Baillet | G3: Nicolas Bresch | H3: Quentin Briard | I3: Nicolas Caussin | J3: Amina Chaabane | K3: Siddhartha Chatterjee | L3: Julien Denis | M3: Caroline Launois-Beaurain | N3: Armelle Vimont Laurent | O3: Sophie Parisot Bouelam | P3: Franck Picabea | Q3: Yoann Spadavecchia | R3: Richard Douville | S3: Score (0–5) | T3: Score Final
B4: Valeur Business | T4: =AVERAGE(S5:S9) -> 4.0923077
C5: Impact métier | D5: A quel point le cas d’usage adresse-t-il un pain point clair, prioritaire et concret (coûts, délais, qualité, satisfaction client, risques) ? | E5: 0 = aucun paint point identifié / 5 = pain point avec fort impact et reconnu | F5: 5 | G5: 4 | H5: 5 | I5: 5 | J5: 4 | K5: 5 | L5: 5 | M5: 4 | N5: 4 | O5: 5 | P5: 3 | Q5: 4 | R5: 4 | S5: =AVERAGE(F5:R5) -> 4.3846154
C6: Viabilité économique | D6: A quel point le cas d'usage présente-t-il un potentiel de ROI crédible et réaliste (économies, gains de productivité, amélioration de la qualité) ? | E6: 0 = aucun ROI objectivé / 5 = ROI clair et élévé | F6: 3 | G6: 2 | H6: 3 | I6: 4 | J6: 3 | K6: 4 | L6: 4 | M6: 3 | N6: 4 | O6: 3 | P6: 2 | Q6: 1 | R6: 3 | S6: =AVERAGE(F6:R6) -> 3
C7: Automatisation | D7: A quel niveau la solution permet-elle d’automatiser un processus métier (vs simple aide ponctuelle) ? | E7: 0 = aide marginale / 5 = automatisation de bout en bout | F7: 4 | G7: 5 | H7: 5 | I7: 5 | J7: 4 | K7: 5 | L7: 5 | M7: 5 | N7: 4 | O7: 5 | P7: 4 | Q7: 5 | R7: 4 | S7: =AVERAGE(F7:R7) -> 4.6153846
C8: Effet différenciant | D8: Ce cas d’usage a-t-il un potentiel de transformation visible ("whaou") pour nos métiers ou clients ? | E8: 0 – Aucun effet différenciant / 5 – Effet “Whaou” stratégique | F8: 4 | G8: 4 | H8: 5 | I8: 5 | J8: 4 | K8: 4 | L8: 4 | M8: 5 | N8: 4 | O8: 5 | P8: 4 | Q8: 2 | R8: 3 | S8: =AVERAGE(F8:R8) -> 4.0769231
C9: Cohérence stratégique | D9: A quel point le cas d’usage est aligné avec les priorités stratégiques Club Med (excellence opérationnelle, expérience client, scalabilité) au-delà d'un besoin local ? | E9: 0 = aucun lien avec la stratégie / 5 = alignement majeur | F9: 5 | G9: 4 | H9: 5 | I9: 5 | J9: 4 | K9: 5 | L9: 5 | M9: 4 | N9: 4 | O9: 5 | P9: 3 | Q9: 4 | R9: 4 | S9: =AVERAGE(F9:R9) -> 4.3846154
B10: Maturité du Use Case | T10: =AVERAGE(S11:S15) -> 3.1834499
C11: Qualité du cadrage fonctionnel | D11: A quel niveau le périmètre, les objectifs et les hypothèses sont-ils clairement définis ? | E11: 0 = très flou / 5 = cadrage exemplaire | F11: 4 | G11: 3 | H11: 5 | I11: 5 | J11: 4 | K11: 4 | L11: 5 | M11: 4 | N11: 5 | O11: 5 | P11: 3 | Q11: 5 | R11: 3 | S11: =+AVERAGE(F11:R11) -> 4.2307692
C12: Accessibilité / Disponiblité des données | D12: A quel point les données nécessaires sont-elles identifiées, existantes et accessibles (CRM, formulaires, historiques, etc.) ? | E12: 0 = données inexistantes / 5 = données prêtes à l'emploi | F12: 4 | G12: 4 | H12: 5 | I12: 5 | J12: 4 | K12: 3 | L12: 4 | M12: 5 | N12: 4 | O12: 5 | P12: 4 | Q12: 5 | R12: 4 | S12: =+AVERAGE(F12:R12) -> 4.3076923
C13: Maturité POC / Hackathon | D13: Compte tenu des données, du cadrage et des dépendances, peut-on produire un résultat concret en hackathon ? | E13: 0 = irréaliste / 5 = hackaton ready | F13: 3 | G13: 3 | H13: 3 | I13: 4 | K13: 5 | L13: 5 | M13: 4 | N13: 3 | O13: 4 | P13: 3 | Q13: 5 | R13: 4 | S13: =+AVERAGE(F13:R13) -> 3.8333333
C14: Scalabilité technique | D14: Dans quelle mesure les technologies envisagées sont-elles mutualisables et industrialisables ? | E14: 0 = non scalable / 5 = scalabilité native | F14: 3 | G14: 3 | H14: 2 | I14: 1 | K14: 4 | L14: 5 | M14: 4 | N14: 3 | O14: 3 | P14: 2 | Q14: 3 | R14: 3 | S14: =+AVERAGE(F14:R14) -> 3
C15: Confidentialité des données | D15: A quel point les enjeux de confidentialité, de sécurité et de conformité RGPD sont ils maîtrisés et compatibles avec une mise en œuvre de ce cas d'usage ? | E15: 0 = risque majeur / 5 = conformité by design | F15: 0 | G15: 0 | H15: 0 | I15: 0 | K15: 3 | L15: 3 | N15: 0 | O15: 0 | P15: 0 | Q15: 0 | R15: 0 | S15: =+AVERAGE(F15:R15) -> 0.54545455
B17: RESULTATS CONSOLIDES
B18: Ce scoring vous permettra de projeter ces différents cas d'usage sur la matrice pour une vue consolidée finale.
B20: =B4 -> Valeur Business | C20: =T4 -> 4.0923077 | D20: =IF(C20<2.5,"Faible",IF(AND(C20>=2.5,C20<4),"Moyen","Fort")) -> Fort
B21: =B10 -> Maturité du Use Case | C21: =T10 -> 3.1834499 | D21: =IF(C21<2.5,"Faible",IF(AND(C21>=2.5,C21<4),"Moyen","Fort")) -> Moyen
B24: POSITIONNEMENT FINAL : - Sélectionné pour le hackathon - Backlog pour les squads IA - A développer en self-service
B26: =IF(C20<3,"Hors priorité", IF(AND(C20>=4,C21>=4),"Hackathon", IF(AND(C20>=4,C21<4),"Backlog projet", IF(AND(C20>=3,C20<4,C21>=4),"Self AI (Copilot Studio)", "Backlog projet" ) ) ) ) -> Backlog projet
B28: Légende :
B29: Valeur < 3 - Hors priorité Valeur ≥ 4 & Faisabilité ≥ 4 - Hackathon Valeur ≥ 4 & Faisabilité < 4 - Backlog projet Valeur entre 3 et <4 & Faisabilité ≥ 4 - Self AI Autre - Backlog projet (par défaut)

Sheet Language Assessment
B2: Use case # 7 | C2: Language Assessment
B3: Thème | C3: Critère | D3: Description | E3: Echelle | F3: Cédric Baillet | G3: Nicolas Bresch | H3: Quentin Briard | I3: Nicolas Caussin | J3: Amina Chaabane | K3: Siddhartha Chatterjee | L3: Julien Denis | M3: Caroline Launois-Beaurain | N3: Armelle Vimont Laurent | O3: Sophie Parisot Bouelam | P3: Franck Picabea | Q3: Yoann Spadavecchia | R3: Richard Douville | S3: Score (0–5) | T3: Score Final
B4: Valeur Business | T4: =AVERAGE(S5:S9) -> 3.6769231
C5: Impact métier | D5: A quel point le cas d’usage adresse-t-il un pain point clair, prioritaire et concret (coûts, délais, qualité, satisfaction client, risques) ? | E5: 0 = aucun paint point identifié / 5 = pain point avec fort impact et reconnu | F5: 5 | G5: 5 | H5: 5 | I5: 4 | J5: 4 | K5: 5 | L5: 5 | M5: 4 | N5: 4 | O5: 4 | P5: 4 | Q5: 4 | R5: 4 | S5: =AVERAGE(F5:R5) -> 4.3846154
C6: Viabilité économique | D6: A quel point le cas d'usage présente-t-il un potentiel de ROI crédible et réaliste (économies, gains de productivité, amélioration de la qualité) ? | E6: 0 = aucun ROI objectivé / 5 = ROI clair et élévé | F6: 3 | G6: 4 | H6: 4 | I6: 4 | J6: 2 | K6: 4 | L6: 3 | M6: 3 | N6: 4 | O6: 4 | P6: 3 | Q6: 2 | R6: 2 | S6: =AVERAGE(F6:R6) -> 3.2307692
C7: Automatisation | D7: A quel niveau la solution permet-elle d’automatiser un processus métier (vs simple aide ponctuelle) ? | E7: 0 = aide marginale / 5 = automatisation de bout en bout | F7: 4 | G7: 4 | H7: 3 | I7: 3 | J7: 3 | K7: 4 | L7: 2 | M7: 2 | N7: 4 | O7: 4 | P7: 3 | Q7: 4 | R7: 3 | S7: =AVERAGE(F7:R7) -> 3.3076923
C8: Effet différenciant | D8: Ce cas d’usage a-t-il un potentiel de transformation visible ("whaou") pour nos métiers ou clients ? | E8: 0 – Aucun effet différenciant / 5 – Effet “Whaou” stratégique | F8: 4 | G8: 4 | H8: 4 | I8: 5 | J8: 4 | K8: 5 | L8: 4 | M8: 3 | N8: 3 | O8: 4 | P8: 3 | Q8: 3 | R8: 3 | S8: =AVERAGE(F8:R8) -> 3.7692308
C9: Cohérence stratégique | D9: A quel point le cas d’usage est aligné avec les priorités stratégiques Club Med (excellence opérationnelle, expérience client, scalabilité) au-delà d'un besoin local ? | E9: 0 = aucun lien avec la stratégie / 5 = alignement majeur | F9: 5 | G9: 4 | H9: 4 | I9: 4 | J9: 3 | K9: 5 | L9: 3 | M9: 3 | N9: 4 | O9: 4 | P9: 3 | Q9: 3 | R9: 3 | S9: =AVERAGE(F9:R9) -> 3.6923077
B10: Maturité du Use Case | T10: =AVERAGE(S11:S15) -> 3.1335664
C11: Qualité du cadrage fonctionnel | D11: A quel niveau le périmètre, les objectifs et les hypothèses sont-ils clairement définis ? | E11: 0 = très flou / 5 = cadrage exemplaire | F11: 4 | G11: 3 | H11: 3 | I11: 3 | J11: 3 | K11: 4 | L11: 2 | M11: 3 | N11: 4 | O11: 4 | P11: 2 | Q11: 5 | R11: 4 | S11: =+AVERAGE(F11:R11) -> 3.3846154
C12: Accessibilité / Disponiblité des données | D12: A quel point les données nécessaires sont-elles identifiées, existantes et accessibles (CRM, formulaires, historiques, etc.) ? | E12: 0 = données inexistantes / 5 = données prêtes à l'emploi | F12: 4 | G12: 3 | H12: 4 | I12: 4 | J12: 3 | K12: 5 | L12: 3 | M12: 4 | N12: 3 | O12: 3 | P12: 4 | Q12: 4 | R12: 4 | S12: =+AVERAGE(F12:R12) -> 3.6923077
C13: Maturité POC / Hackathon | D13: Compte tenu des données, du cadrage et des dépendances, peut-on produire un résultat concret en hackathon ? | E13: 0 = irréaliste / 5 = hackaton ready | F13: 4 | G13: 4 | H13: 4 | I13: 5 | K13: 5 | L13: 5 | M13: 4 | N13: 4 | O13: 3 | P13: 4 | Q13: 4 | R13: 4 | S13: =+AVERAGE(F13:R13) -> 4.1666667
C14: Scalabilité technique | D14: Dans quelle mesure les technologies envisagées sont-elles mutualisables et industrialisables ? | E14: 0 = non scalable / 5 = scalabilité native | F14: 1 | G14: 3 | H14: 2 | I14: 2 | K14: 4 | L14: 5 | M14: 3 | N14: 4 | O14: 5 | P14: 4 | Q14: 4 | R14: 3 | S14: =+AVERAGE(F14:R14) -> 3.3333333
C15: Confidentialité des données | D15: A quel point les enjeux de confidentialité, de sécurité et de conformité RGPD sont ils maîtrisés et compatibles avec une mise en œuvre de ce cas d'usage ? | E15: 0 = risque majeur / 5 = conformité by design | F15: 0 | G15: 1 | H15: 0 | I15: 2 | K15: 4 | L15: 0 | N15: 1 | O15: 1 | P15: 1 | Q15: 1 | R15: 1 | S15: =+AVERAGE(F15:R15) -> 1.0909091
B17: RESULTATS CONSOLIDES
B18: Ce scoring vous permettra de projeter ces différents cas d'usage sur la matrice pour une vue consolidée finale.
B20: =B4 -> Valeur Business | C20: =T4 -> 3.6769231 | D20: =IF(C20<2.5,"Faible",IF(AND(C20>=2.5,C20<4),"Moyen","Fort")) -> Moyen
B21: =B10 -> Maturité du Use Case | C21: =T10 -> 3.1335664 | D21: =IF(C21<2.5,"Faible",IF(AND(C21>=2.5,C21<4),"Moyen","Fort")) -> Moyen
B24: POSITIONNEMENT FINAL : - Sélectionné pour le hackathon - Backlog pour les squads IA - A développer en self-service
B26: =IF(C20<3,"Hors priorité", IF(AND(C20>=4,C21>=4),"Hackathon", IF(AND(C20>=4,C21<4),"Backlog projet", IF(AND(C20>=3,C20<4,C21>=4),"Self AI (Copilot Studio)", "Backlog projet" ) ) ) ) -> Backlog projet
B28: Légende :
B29: Valeur < 3 - Hors priorité Valeur ≥ 4 & Faisabilité ≥ 4 - Hackathon Valeur ≥ 4 & Faisabilité < 4 - Backlog projet Valeur entre 3 et <4 & Faisabilité ≥ 4 - Self AI Autre - Backlog projet (par défaut)

Sheet Reception Email
B2: Use case # 5 | C2: Reception Email
B3: Thème | C3: Critère | D3: Description | E3: Echelle | F3: Cédric Baillet | G3: Nicolas Bresch | H3: Quentin Briard | I3: Nicolas Caussin | J3: Amina Chaabane | K3: Siddhartha Chatterjee | L3: Julien Denis | M3: Caroline Launois-Beaurain | N3: Armelle Vimont Laurent | O3: Sophie Parisot Bouelam | P3: Franck Picabea | Q3: Yoann Spadavecchia | R3: Richard Douville | S3: Score (0–5) | T3: Score Final
B4: Valeur Business | T4: =AVERAGE(S5:S9) -> 4.3538462
C5: Impact métier | D5: A quel point le cas d’usage adresse-t-il un pain point clair, prioritaire et concret (coûts, délais, qualité, satisfaction client, risques) ? | E5: 0 = aucun paint point identifié / 5 = pain point avec fort impact et reconnu | F5: 4 | G5: 5 | H5: 5 | I5: 5 | J5: 5 | K5: 5 | L5: 4 | M5: 5 | N5: 5 | O5: 4 | P5: 5 | Q5: 5 | R5: 5 | S5: =AVERAGE(F5:R5) -> 4.7692308
C6: Viabilité économique | D6: A quel point le cas d'usage présente-t-il un potentiel de ROI crédible et réaliste (économies, gains de productivité, amélioration de la qualité) ? | E6: 0 = aucun ROI objectivé / 5 = ROI clair et élévé | F6: 3 | G6: 5 | H6: 5 | I6: 5 | J6: 5 | K6: 4 | L6: 5 | M6: 4 | N6: 4 | O6: 4 | P6: 3 | Q6: 1 | R6: 3 | S6: =AVERAGE(F6:R6) -> 3.9230769
C7: Automatisation | D7: A quel niveau la solution permet-elle d’automatiser un processus métier (vs simple aide ponctuelle) ? | E7: 0 = aide marginale / 5 = automatisation de bout en bout | F7: 3 | G7: 5 | H7: 5 | I7: 5 | J7: 4 | K7: 3 | L7: 3 | M7: 5 | N7: 5 | O7: =9 - J7 -> 5 | P7: 5 | Q7: 4 | R7: 4 | S7: =AVERAGE(F7:R7) -> 4.3076923
C8: Effet différenciant | D8: Ce cas d’usage a-t-il un potentiel de transformation visible ("whaou") pour nos métiers ou clients ? | E8: 0 – Aucun effet différenciant / 5 – Effet “Whaou” stratégique | F8: 3 | G8: 5 | H8: 5 | I8: 5 | J8: 5 | K8: 4 | L8: 3 | M8: 5 | N8: 5 | O8: =9 - J8 -> 4 | P8: 4 | Q8: 4 | R8: 4 | S8: =AVERAGE(F8:R8) -> 4.3076923
C9: Cohérence stratégique | D9: A quel point le cas d’usage est aligné avec les priorités stratégiques Club Med (excellence opérationnelle, expérience client, scalabilité) au-delà d'un besoin local ? | E9: 0 = aucun lien avec la stratégie / 5 = alignement majeur | F9: 4 | G9: 5 | H9: 5 | I9: 5 | J9: 5 | K9: 4 | L9: 3 | M9: 5 | N9: 5 | O9: =9 - J9 -> 4 | P9: 4 | Q9: 5 | R9: 4 | S9: =AVERAGE(F9:R9) -> 4.4615385
B10: Maturité du Use Case | T10: =AVERAGE(S11:S15) -> 3.9918415
C11: Qualité du cadrage fonctionnel | D11: A quel niveau le périmètre, les objectifs et les hypothèses sont-ils clairement définis ? | E11: 0 = très flou / 5 = cadrage exemplaire | F11: 4 | G11: 4 | H11: 5 | I11: 4 | J11: 5 | K11: 4 | L11: 4 | M11: 5 | N11: 4 | O11: =9 - J11 -> 4 | P11: 4 | Q11: 5 | R11: 5 | S11: =+AVERAGE(F11:R11) -> 4.3846154
C12: Accessibilité / Disponiblité des données | D12: A quel point les données nécessaires sont-elles identifiées, existantes et accessibles (CRM, formulaires, historiques, etc.) ? | E12: 0 = données inexistantes / 5 = données prêtes à l'emploi | F12: 5 | G12: 4 | H12: 4 | I12: 4 | J12: 4 | K12: 3 | L12: 4 | M12: 4 | N12: 3 | O12: 4 | P12: 4 | Q12: 3 | R12: 5 | S12: =+AVERAGE(F12:R12) -> 3.9230769
C13: Maturité POC / Hackathon | D13: Compte tenu des données, du cadrage et des dépendances, peut-on produire un résultat concret en hackathon ? | E13: 0 = irréaliste / 5 = hackaton ready | F13: 5 | G13: 5 | H13: 5 | I13: 5 | K13: 4 | L13: 5 | M13: 4 | N13: 4 | O13: 4 | P13: 5 | Q13: 5 | R13: 4 | S13: =+AVERAGE(F13:R13) -> 4.5833333
C14: Scalabilité technique | D14: Dans quelle mesure les technologies envisagées sont-elles mutualisables et industrialisables ? | E14: 0 = non scalable / 5 = scalabilité native | F14: 4 | G14: 5 | H14: 4 | I14: 4 | K14: 3 | L14: 5 | M14: 5 | N14: 4 | O14: 4 | P14: 4 | Q14: 5 | R14: 4 | S14: =+AVERAGE(F14:R14) -> 4.25
C15: Confidentialité des données | D15: A quel point les enjeux de confidentialité, de sécurité et de conformité RGPD sont ils maîtrisés et compatibles avec une mise en œuvre de ce cas d'usage ? | E15: 0 = risque majeur / 5 = conformité by design | F15: 3 | G15: 3 | H15: 3 | I15: 3 | K15: 3 | L15: 3 | N15: 2 | O15: 2 | P15: 3 | Q15: 3 | R15: 3 | S15: =+AVERAGE(F15:R15) -> 2.8181818
B17: RESULTATS CONSOLIDES
B18: Ce scoring vous permettra de projeter ces différents cas d'usage sur la matrice pour une vue consolidée finale.
B20: =B4 -> Valeur Business | C20: =T4 -> 4.3538462 | D20: =IF(C20<2.5,"Faible",IF(AND(C20>=2.5,C20<4),"Moyen","Fort")) -> Fort
B21: =B10 -> Maturité du Use Case | C21: =T10 -> 3.9918415 | D21: =IF(C21<2.5,"Faible",IF(AND(C21>=2.5,C21<4),"Moyen","Fort")) -> Moyen
B24: POSITIONNEMENT FINAL : - Sélectionné pour le hackathon - Backlog pour les squads IA - A développer en self-service
B26: =IF(C20<3,"Hors priorité", IF(AND(C20>=4,C21>=4),"Hackathon", IF(AND(C20>=4,C21<4),"Backlog projet", IF(AND(C20>=3,C20<4,C21>=4),"Self AI (Copilot Studio)", "Backlog projet" ) ) ) ) -> Backlog projet
B28: Légende :
B29: Valeur < 3 - Hors priorité Valeur ≥ 4 & Faisabilité ≥ 4 - Hackathon Valeur ≥ 4 & Faisabilité < 4 - Backlog projet Valeur entre 3 et <4 & Faisabilité ≥ 4 - Self AI Autre - Backlog projet (par défaut)

Sheet AD Program
B2: Use case # 8 | C2: A/D Program
B3: Thème | C3: Critère | D3: Description | E3: Echelle | F3: Cédric Baillet | G3: Nicolas Bresch | H3: Quentin Briard | I3: Nicolas Caussin | J3: Amina Chaabane | K3: Siddhartha Chatterjee | L3: Julien Denis | M3: Caroline Launois-Beaurain | N3: Armelle Vimont Laurent | O3: Sophie Parisot Bouelam | P3: Franck Picabea | Q3: Yoann Spadavecchia | R3: Richard Douville | S3: Score (0–5) | T3: Score Final
B4: Valeur Business | T4: =AVERAGE(S5:S9) -> 3.2461538
C5: Impact métier | D5: A quel point le cas d’usage adresse-t-il un pain point clair, prioritaire et concret (coûts, délais, qualité, satisfaction client, risques) ? | E5: 0 = aucun paint point identifié / 5 = pain point avec fort impact et reconnu | F5: 4 | G5: 4 | H5: 4 | I5: 4 | J5: 4 | K5: 4 | L5: 4 | M5: 4 | N5: 4 | O5: 5 | P5: 4 | Q5: 4 | R5: 4 | S5: =AVERAGE(F5:R5) -> 4.0769231
C6: Viabilité économique | D6: A quel point le cas d'usage présente-t-il un potentiel de ROI crédible et réaliste (économies, gains de productivité, amélioration de la qualité) ? | E6: 0 = aucun ROI objectivé / 5 = ROI clair et élévé | F6: 2 | G6: 2 | H6: 1 | I6: 3 | J6: 3 | K6: 3 | L6: 2 | M6: 2 | N6: 3 | O6: 3 | P6: 3 | Q6: 1 | R6: 3 | S6: =AVERAGE(F6:R6) -> 2.3846154
C7: Automatisation | D7: A quel niveau la solution permet-elle d’automatiser un processus métier (vs simple aide ponctuelle) ? | E7: 0 = aide marginale / 5 = automatisation de bout en bout | F7: 4 | G7: 4 | H7: 3 | I7: 4 | J7: 3 | K7: 4 | L7: 5 | M7: 4 | N7: 4 | O7: 5 | P7: 3 | Q7: 3 | R7: 3 | S7: =AVERAGE(F7:R7) -> 3.7692308
C8: Effet différenciant | D8: Ce cas d’usage a-t-il un potentiel de transformation visible ("whaou") pour nos métiers ou clients ? | E8: 0 – Aucun effet différenciant / 5 – Effet “Whaou” stratégique | F8: 3 | G8: 3 | H8: 2 | I8: 3 | J8: 4 | K8: 3 | L8: 2 | M8: 2 | N8: 3 | O8: 4 | P8: 3 | Q8: 1 | R8: 2 | S8: =AVERAGE(F8:R8) -> 2.6923077
C9: Cohérence stratégique | D9: A quel point le cas d’usage est aligné avec les priorités stratégiques Club Med (excellence opérationnelle, expérience client, scalabilité) au-delà d'un besoin local ? | E9: 0 = aucun lien avec la stratégie / 5 = alignement majeur | F9: 5 | G9: 3 | H9: 2 | I9: 3 | J9: 4 | K9: 4 | L9: 2 | M9: 3 | N9: 3 | O9: 5 | P9: 3 | Q9: 3 | R9: 3 | S9: =AVERAGE(F9:R9) -> 3.3076923
B10: Maturité du Use Case | T10: =AVERAGE(S11:S15) -> 2.6837995
C11: Qualité du cadrage fonctionnel | D11: A quel niveau le périmètre, les objectifs et les hypothèses sont-ils clairement définis ? | E11: 0 = très flou / 5 = cadrage exemplaire | F11: 4 | G11: 2 | H11: 4 | I11: 3 | J11: 4 | K11: 4 | L11: 4 | M11: 3 | N11: 4 | O11: 3 | P11: 3 | Q11: 3 | R11: 3 | S11: =+AVERAGE(F11:R11) -> 3.3846154
C12: Accessibilité / Disponiblité des données | D12: A quel point les données nécessaires sont-elles identifiées, existantes et accessibles (CRM, formulaires, historiques, etc.) ? | E12: 0 = données inexistantes / 5 = données prêtes à l'emploi | F12: 3 | G12: 2 | H12: 3 | I12: 3 | J12: 4 | K12: 3 | L12: 1 | M12: 3 | N12: 3 | O12: 4 | P12: 1 | Q12: 4 | R12: 2 | S12: =+AVERAGE(F12:R12) -> 2.7692308
C13: Maturité POC / Hackathon | D13: Compte tenu des données, du cadrage et des dépendances, peut-on produire un résultat concret en hackathon ? | E13: 0 = irréaliste / 5 = hackaton ready | F13: 2 | G13: 3 | H13: 3 | I13: 3 | K13: 3 | L13: 5 | M13: 3 | N13: 3 | O13: 4 | P13: 3 | Q13: 2 | R13: 3 | S13: =+AVERAGE(F13:R13) -> 3.0833333
C14: Scalabilité technique | D14: Dans quelle mesure les technologies envisagées sont-elles mutualisables et industrialisables ? | E14: 0 = non scalable / 5 = scalabilité native | F14: 1 | G14: 3 | H14: 1 | I14: 3 | K14: 3 | L14: 1 | M14: 2 | N14: 2 | O14: 3 | P14: 2 | Q14: 1 | R14: 2 | S14: =+AVERAGE(F14:R14) -> 2
C15: Confidentialité des données | D15: A quel point les enjeux de confidentialité, de sécurité et de conformité RGPD sont ils maîtrisés et compatibles avec une mise en œuvre de ce cas d'usage ? | E15: 0 = risque majeur / 5 = conformité by design | F15: 1 | G15: 2 | H15: 2 | I15: 2 | K15: 4 | L15: 2 | N15: 1 | O15: 3 | P15: 2 | Q15: 2 | R15: 3 | S15: =+AVERAGE(F15:R15) -> 2.1818182
Q16: Pas un projet IA
B17: RESULTATS CONSOLIDES | Q17: Corriger N/A vers PMS
B18: Ce scoring vous permettra de projeter ces différents cas d'usage sur la matrice pour une vue consolidée finale.
B20: =B4 -> Valeur Business | C20: =T4 -> 3.2461538 | D20: =IF(C20<2.5,"Faible",IF(AND(C20>=2.5,C20<4),"Moyen","Fort")) -> Moyen
B21: =B10 -> Maturité du Use Case | C21: =T10 -> 2.6837995 | D21: =IF(C21<2.5,"Faible",IF(AND(C21>=2.5,C21<4),"Moyen","Fort")) -> Moyen
B24: POSITIONNEMENT FINAL : - Sélectionné pour le hackathon - Backlog pour les squads IA - A développer en self-service
B26: =IF(C20<3,"Hors priorité", IF(AND(C20>=4,C21>=4),"Hackathon", IF(AND(C20>=4,C21<4),"Backlog projet", IF(AND(C20>=3,C20<4,C21>=4),"Self AI (Copilot Studio)", "Backlog projet" ) ) ) ) -> Backlog projet
B28: Légende :
B29: Valeur < 3 - Hors priorité Valeur ≥ 4 & Faisabilité ≥ 4 - Hackathon Valeur ≥ 4 & Faisabilité < 4 - Backlog projet Valeur entre 3 et <4 & Faisabilité ≥ 4 - Self AI Autre - Backlog projet (par défaut)

Sheet Intelligence Gateway
B2: Use case # 9 | C2: Intelligence Gateway
B3: Thème | C3: Critère | D3: Description | E3: Echelle | F3: Cédric Baillet | G3: Nicolas Bresch | H3: Quentin Briard | I3: Nicolas Caussin | J3: Amina Chaabane | K3: Siddhartha Chatterjee | L3: Julien Denis | M3: Caroline Launois-Beaurain | N3: Armelle Vimont Laurent | O3: Sophie Parisot Bouelam | P3: Franck Picabea | Q3: Yoann Spadavecchia | R3: Richard Douville | S3: Score (0–5) | T3: Score Final
B4: Valeur Business | T4: =AVERAGE(S5:S9) -> 2.9384615
C5: Impact métier | D5: A quel point le cas d’usage adresse-t-il un pain point clair, prioritaire et concret (coûts, délais, qualité, satisfaction client, risques) ? | E5: 0 = aucun paint point identifié / 5 = pain point avec fort impact et reconnu | F5: 3 | G5: 5 | H5: 3 | I5: 4 | J5: 4 | K5: 4 | L5: 3 | M5: 4 | N5: 3 | O5: 4 | P5: 3 | Q5: 5 | R5: 3 | S5: =AVERAGE(F5:R5) -> 3.6923077
C6: Viabilité économique | D6: A quel point le cas d'usage présente-t-il un potentiel de ROI crédible et réaliste (économies, gains de productivité, amélioration de la qualité) ? | E6: 0 = aucun ROI objectivé / 5 = ROI clair et élévé | F6: 3 | G6: 4 | H6: 0 | I6: 3 | J6: 2 | K6: 2 | L6: 2 | M6: 3 | N6: 2 | O6: 2 | P6: 2 | Q6: 4 | R6: 2 | S6: =AVERAGE(F6:R6) -> 2.3846154
C7: Automatisation | D7: A quel niveau la solution permet-elle d’automatiser un processus métier (vs simple aide ponctuelle) ? | E7: 0 = aide marginale / 5 = automatisation de bout en bout | F7: 3 | G7: 4 | H7: 0 | I7: 2 | J7: 2 | K7: 3 | L7: 1 | M7: 3 | N7: 2 | O7: 2 | P7: 3 | Q7: 2 | R7: 2 | S7: =AVERAGE(F7:R7) -> 2.2307692
C8: Effet différenciant | D8: Ce cas d’usage a-t-il un potentiel de transformation visible ("whaou") pour nos métiers ou clients ? | E8: 0 – Aucun effet différenciant / 5 – Effet “Whaou” stratégique | F8: 3 | G8: 3 | H8: 3 | I8: 3 | J8: 4 | K8: 3 | L8: 2 | M8: 3 | N8: 3 | O8: 3 | P8: 3 | Q8: 4 | R8: 3 | S8: =AVERAGE(F8:R8) -> 3.0769231
C9: Cohérence stratégique | D9: A quel point le cas d’usage est aligné avec les priorités stratégiques Club Med (excellence opérationnelle, expérience client, scalabilité) au-delà d'un besoin local ? | E9: 0 = aucun lien avec la stratégie / 5 = alignement majeur | F9: 3 | G9: 4 | H9: 3 | I9: 4 | J9: 3 | K9: 4 | L9: 2 | M9: 4 | N9: 3 | O9: 4 | P9: 2 | Q9: 4 | R9: 3 | S9: =AVERAGE(F9:R9) -> 3.3076923
B10: Maturité du Use Case | T10: =AVERAGE(S11:S15) -> 3.9121212
C11: Qualité du cadrage fonctionnel | D11: A quel niveau le périmètre, les objectifs et les hypothèses sont-ils clairement définis ? | E11: 0 = très flou / 5 = cadrage exemplaire | F11: 4 | G11: 4 | H11: 4 | I11: 3 | J11: 4 | K11: 3 | L11: 3 | M11: 4 | N11: 4 | O11: 3 | P11: 4 | Q11: 5 | R11: 4 | S11: =+AVERAGE(F11:R11) -> 3.7692308
C12: Accessibilité / Disponiblité des données | D12: A quel point les données nécessaires sont-elles identifiées, existantes et accessibles (CRM, formulaires, historiques, etc.) ? | E12: 0 = données inexistantes / 5 = données prêtes à l'emploi | F12: 2 | G12: 4 | H12: 3 | I12: 3 | J12: 2 | K12: 2 | L12: 4 | M12: 5 | N12: 4 | O12: 2 | P12: 4 | Q12: 3 | R12: 4 | S12: =+AVERAGE(F12:R12) -> 3.2307692
C13: Maturité POC / Hackathon | D13: Compte tenu des données, du cadrage et des dépendances, peut-on produire un résultat concret en hackathon ? | E13: 0 = irréaliste / 5 = hackaton ready | F13: 3 | G13: 4 | H13: 4 | I13: 3 | K13: 3 | L13: 4 | M13: 4 | N13: 4 | O13: 3 | P13: 4 | Q13: 4 | R13: 4 | S13: =+AVERAGE(F13:R13) -> 3.6666667
C14: Scalabilité technique | D14: Dans quelle mesure les technologies envisagées sont-elles mutualisables et industrialisables ? | E14: 0 = non scalable / 5 = scalabilité native | F14: 4 | G14: 5 | H14: 5 | I14: 4 | K14: 3 | L14: 4 | M14: 5 | N14: 4 | O14: 4 | P14: 3 | Q14: 5 | R14: 4 | S14: =+AVERAGE(F14:R14) -> 4.1666667
C15: Confidentialité des données | D15: A quel point les enjeux de confidentialité, de sécurité et de conformité RGPD sont ils maîtrisés et compatibles avec une mise en œuvre de ce cas d'usage ? | E15: 0 = risque majeur / 5 = conformité by design | F15: 4 | G15: 4 | H15: 5 | I15: 4 | K15: 5 | L15: 5 | N15: 5 | O15: 5 | P15: 5 | Q15: 5 | R15: 5 | S15: =+AVERAGE(F15:R15) -> 4.7272727
H16: Attention pas un process
B17: RESULTATS CONSOLIDES
B18: Ce scoring vous permettra de projeter ces différents cas d'usage sur la matrice pour une vue consolidée finale.
B20: =B4 -> Valeur Business | C20: =T4 -> 2.9384615 | D20: =IF(C20<2.5,"Faible",IF(AND(C20>=2.5,C20<4),"Moyen","Fort")) -> Moyen
B21: =B10 -> Maturité du Use Case | C21: =T10 -> 3.9121212 | D21: =IF(C21<2.5,"Faible",IF(AND(C21>=2.5,C21<4),"Moyen","Fort")) -> Moyen
B24: POSITIONNEMENT FINAL : - Sélectionné pour le hackathon - Backlog pour les squads IA - A développer en self-service
B26: =IF(C20<3,"Hors priorité", IF(AND(C20>=4,C21>=4),"Hackathon", IF(AND(C20>=4,C21<4),"Backlog projet", IF(AND(C20>=3,C20<4,C21>=4),"Self AI (Copilot Studio)", "Backlog projet" ) ) ) ) -> Hors priorité
B28: Légende :
B29: Valeur < 3 - Hors priorité Valeur ≥ 4 & Faisabilité ≥ 4 - Hackathon Valeur ≥ 4 & Faisabilité < 4 - Backlog projet Valeur entre 3 et <4 & Faisabilité ≥ 4 - Self AI Autre - Backlog projet (par défaut)

Sheet Flight Schedule
B2: Use case # 10 | C2: Flight Schedule
B3: Thème | C3: Critère | D3: Description | E3: Echelle | F3: Cédric Baillet | G3: Nicolas Bresch | H3: Quentin Briard | I3: Nicolas Caussin | J3: Amina Chaabane | K3: Siddhartha Chatterjee | L3: Julien Denis | M3: Caroline Launois-Beaurain | N3: Armelle Vimont Laurent | O3: Sophie Parisot Bouelam | P3: Franck Picabea | Q3: Yoann Spadavecchia | R3: Richard Douville | S3: Score (0–5) | T3: Score Final
B4: Valeur Business | T4: =AVERAGE(S5:S9) -> 4.2153846
C5: Impact métier | D5: A quel point le cas d’usage adresse-t-il un pain point clair, prioritaire et concret (coûts, délais, qualité, satisfaction client, risques) ? | E5: 0 = aucun paint point identifié / 5 = pain point avec fort impact et reconnu | F5: 4 | G5: 5 | H5: 5 | I5: 4 | J5: 4 | K5: 5 | L5: 5 | M5: 5 | N5: 4 | O5: 5 | P5: 4 | Q5: 5 | R5: 4 | S5: =AVERAGE(F5:R5) -> 4.5384615
C6: Viabilité économique | D6: A quel point le cas d'usage présente-t-il un potentiel de ROI crédible et réaliste (économies, gains de productivité, amélioration de la qualité) ? | E6: 0 = aucun ROI objectivé / 5 = ROI clair et élévé | F6: 4 | G6: 5 | H6: 4 | I6: 4 | J6: 3 | K6: 3 | L6: 4 | M6: 5 | N6: 4 | O6: 4 | P6: 4 | Q6: 3 | R6: 3 | S6: =AVERAGE(F6:R6) -> 3.8461538
C7: Automatisation | D7: A quel niveau la solution permet-elle d’automatiser un processus métier (vs simple aide ponctuelle) ? | E7: 0 = aide marginale / 5 = automatisation de bout en bout | F7: 5 | G7: 5 | H7: 5 | I7: 5 | J7: 5 | K7: 4 | L7: 5 | M7: 5 | N7: 5 | O7: 5 | P7: 3 | Q7: 3 | R7: 3 | S7: =AVERAGE(F7:R7) -> 4.4615385
C8: Effet différenciant | D8: Ce cas d’usage a-t-il un potentiel de transformation visible ("whaou") pour nos métiers ou clients ? | E8: 0 – Aucun effet différenciant / 5 – Effet “Whaou” stratégique | F8: 4 | G8: 4 | H8: 4 | I8: 4 | J8: 4 | K8: 4 | L8: 4 | M8: 4 | N8: 4 | O8: 5 | P8: 4 | Q8: 4 | R8: 4 | S8: =AVERAGE(F8:R8) -> 4.0769231
C9: Cohérence stratégique | D9: A quel point le cas d’usage est aligné avec les priorités stratégiques Club Med (excellence opérationnelle, expérience client, scalabilité) au-delà d'un besoin local ? | E9: 0 = aucun lien avec la stratégie / 5 = alignement majeur | F9: 5 | G9: 5 | H9: 4 | I9: 4 | J9: 4 | K9: 4 | L9: 4 | M9: 5 | N9: 3 | O9: 4 | P9: 4 | Q9: 4 | R9: 4 | S9: =AVERAGE(F9:R9) -> 4.1538462
B10: Maturité du Use Case | T10: =AVERAGE(S11:S15) -> 3.4730769
C11: Qualité du cadrage fonctionnel | D11: A quel niveau le périmètre, les objectifs et les hypothèses sont-ils clairement définis ? | E11: 0 = très flou / 5 = cadrage exemplaire | F11: 3 | G11: 5 | H11: 4 | I11: 3 | J11: 5 | K11: 3 | L11: 4 | M11: 5 | N11: 4 | O11: 3 | P11: 2 | Q11: 2 | R11: 3 | S11: =+AVERAGE(F11:R11) -> 3.5384615
C12: Accessibilité / Disponiblité des données | D12: A quel point les données nécessaires sont-elles identifiées, existantes et accessibles (CRM, formulaires, historiques, etc.) ? | E12: 0 = données inexistantes / 5 = données prêtes à l'emploi | F12: 5 | G12: 4 | H12: 4 | I12: 5 | J12: 4 | K12: 4 | L12: 4 | M12: 4 | N12: 4 | O12: 4 | P12: 4 | Q12: 4 | R12: 3 | S12: =+AVERAGE(F12:R12) -> 4.0769231
C13: Maturité POC / Hackathon | D13: Compte tenu des données, du cadrage et des dépendances, peut-on produire un résultat concret en hackathon ? | E13: 0 = irréaliste / 5 = hackaton ready | F13: 1 | G13: 5 | H13: 2 | I13: 3 | K13: 4 | L13: 2 | M13: 4 | N13: 4 | O13: 4 | P13: 4 | Q13: 3 | R13: 3 | S13: =+AVERAGE(F13:R13) -> 3.25
C14: Scalabilité technique | D14: Dans quelle mesure les technologies envisagées sont-elles mutualisables et industrialisables ? | E14: 0 = non scalable / 5 = scalabilité native | F14: 2 | G14: 5 | H14: 1 | I14: 4 | K14: 3 | L14: 1 | M14: 3 | N14: 3 | O14: 2 | P14: 4 | Q14: 2 | R14: 3 | S14: =+AVERAGE(F14:R14) -> 2.75
C15: Confidentialité des données | D15: A quel point les enjeux de confidentialité, de sécurité et de conformité RGPD sont ils maîtrisés et compatibles avec une mise en œuvre de ce cas d'usage ? | E15: 0 = risque majeur / 5 = conformité by design | F15: 3 | G15: 5 | H15: 3 | I15: 3 | K15: 5 | L15: 3 | M15: 5 | N15: 3 | O15: 4 | P15: 4 | Q15: 3 | R15: 4 | S15: =+AVERAGE(F15:R15) -> 3.75
B17: RESULTATS CONSOLIDES
B18: Ce scoring vous permettra de projeter ces différents cas d'usage sur la matrice pour une vue consolidée finale.
B20: =B4 -> Valeur Business | C20: =T4 -> 4.2153846 | D20: =IF(C20<2.5,"Faible",IF(AND(C20>=2.5,C20<4),"Moyen","Fort")) -> Fort
B21: =B10 -> Maturité du Use Case | C21: =T10 -> 3.4730769 | D21: =IF(C21<2.5,"Faible",IF(AND(C21>=2.5,C21<4),"Moyen","Fort")) -> Moyen
B24: POSITIONNEMENT FINAL : - Sélectionné pour le hackathon - Backlog pour les squads IA - A développer en self-service
B26: =IF(C20<3,"Hors priorité", IF(AND(C20>=4,C21>=4),"Hackathon", IF(AND(C20>=4,C21<4),"Backlog projet", IF(AND(C20>=3,C20<4,C21>=4),"Self AI (Copilot Studio)", "Backlog projet" ) ) ) ) -> Backlog projet
B28: Légende :
B29: Valeur < 3 - Hors priorité Valeur ≥ 4 & Faisabilité ≥ 4 - Hackathon Valeur ≥ 4 & Faisabilité < 4 - Backlog projet Valeur entre 3 et <4 & Faisabilité ≥ 4 - Self AI Autre - Backlog projet (par défaut)

Sheet Automatic Refund
B2: Use case # 11 | C2: Automatic Refund
B3: Thème | C3: Critère | D3: Description | E3: Echelle | F3: Cédric Baillet | G3: Nicolas Bresch | H3: Quentin Briard | I3: Nicolas Caussin | J3: Amina Chaabane | K3: Siddhartha Chatterjee | L3: Julien Denis | M3: Caroline Launois-Beaurain | N3: Armelle Vimont Laurent | O3: Sophie Parisot Bouelam | P3: Franck Picabea | Q3: Yoann Spadavecchia | R3: Richard Douville | S3: Score (0–5) | T3: Score Final
B4: Valeur Business | T4: =AVERAGE(S5:S9) -> 3.4
C5: Impact métier | D5: A quel point le cas d’usage adresse-t-il un pain point clair, prioritaire et concret (coûts, délais, qualité, satisfaction client, risques) ? | E5: 0 = aucun paint point identifié / 5 = pain point avec fort impact et reconnu | F5: 4 | G5: 5 | H5: 4 | I5: 4 | J5: 4 | K5: 4 | L5: 4 | M5: 5 | N5: 5 | O5: 4 | P5: 4 | Q5: 4 | R5: 4 | S5: =AVERAGE(F5:R5) -> 4.2307692
C6: Viabilité économique | D6: A quel point le cas d'usage présente-t-il un potentiel de ROI crédible et réaliste (économies, gains de productivité, amélioration de la qualité) ? | E6: 0 = aucun ROI objectivé / 5 = ROI clair et élévé | F6: 2 | G6: 5 | H6: 2 | I6: 3 | J6: 3 | K6: 2 | L6: 3 | M6: 4 | N6: 2 | O6: 4 | P6: 2 | Q6: 4 | R6: 2 | S6: =AVERAGE(F6:R6) -> 2.9230769
C7: Automatisation | D7: A quel niveau la solution permet-elle d’automatiser un processus métier (vs simple aide ponctuelle) ? | E7: 0 = aide marginale / 5 = automatisation de bout en bout | F7: 4 | G7: 5 | H7: 4 | I7: 5 | J7: 3 | K7: 4 | L7: 4 | M7: 5 | N7: 5 | O7: 4 | P7: 4 | Q7: 4 | R7: 4 | S7: =AVERAGE(F7:R7) -> 4.2307692
C8: Effet différenciant | D8: Ce cas d’usage a-t-il un potentiel de transformation visible ("whaou") pour nos métiers ou clients ? | E8: 0 – Aucun effet différenciant / 5 – Effet “Whaou” stratégique | F8: 2 | G8: 4 | H8: 2 | I8: 3 | J8: 4 | K8: 2 | L8: 2 | M8: 3 | N8: 3 | O8: 3 | P8: 2 | Q8: 2 | R8: 2 | S8: =AVERAGE(F8:R8) -> 2.6153846
C9: Cohérence stratégique | D9: A quel point le cas d’usage est aligné avec les priorités stratégiques Club Med (excellence opérationnelle, expérience client, scalabilité) au-delà d'un besoin local ? | E9: 0 = aucun lien avec la stratégie / 5 = alignement majeur | F9: 4 | G9: 5 | H9: 1 | I9: 3 | J9: 3 | K9: 2 | L9: 3 | M9: 3 | N9: 2 | O9: 4 | P9: 3 | Q9: 3 | R9: 3 | S9: =AVERAGE(F9:R9) -> 3
B10: Maturité du Use Case | T10: =AVERAGE(S11:S15) -> 3.2862471
C11: Qualité du cadrage fonctionnel | D11: A quel niveau le périmètre, les objectifs et les hypothèses sont-ils clairement définis ? | E11: 0 = très flou / 5 = cadrage exemplaire | F11: 5 | G11: 5 | H11: 5 | I11: 4 | J11: 4 | K11: 4 | L11: 5 | M11: 5 | N11: 5 | O11: 4 | P11: 4 | Q11: 5 | R11: 5 | S11: =+AVERAGE(F11:R11) -> 4.6153846
C12: Accessibilité / Disponiblité des données | D12: A quel point les données nécessaires sont-elles identifiées, existantes et accessibles (CRM, formulaires, historiques, etc.) ? | E12: 0 = données inexistantes / 5 = données prêtes à l'emploi | F12: 5 | G12: 5 | H12: 5 | I12: 4 | J12: 2 | K12: 3 | L12: 4 | M12: 4 | N12: 4 | O12: 3 | P12: 4 | Q12: 3 | R12: 4 | S12: =+AVERAGE(F12:R12) -> 3.8461538
C13: Maturité POC / Hackathon | D13: Compte tenu des données, du cadrage et des dépendances, peut-on produire un résultat concret en hackathon ? | E13: 0 = irréaliste / 5 = hackaton ready | F13: 0 | G13: 5 | H13: 2 | I13: 4 | K13: 4 | L13: 4 | M13: 4 | N13: 4 | O13: 3 | P13: 4 | Q13: 3 | R13: 3 | S13: =+AVERAGE(F13:R13) -> 3.3333333
C14: Scalabilité technique | D14: Dans quelle mesure les technologies envisagées sont-elles mutualisables et industrialisables ? | E14: 0 = non scalable / 5 = scalabilité native | F14: 3 | G14: 4 | H14: 3 | I14: 3 | K14: 3 | L14: 2 | M14: 3 | N14: 3 | O14: 3 | P14: 3 | Q14: 3 | R14: 3 | S14: =+AVERAGE(F14:R14) -> 3
